I get this error when uploading files
ERROR:app:Exception on /api/chats/02b11af08e72/drafts/2efa844c-a480-4525-89ed-15990b40ba36/attachments [POST]
Traceback (most recent call last):
  File "C:\Users\delia\AppData\Local\Programs\Python\Python313\Lib\site-packages\flask\app.py", line 1511, in wsgi_app
    response = self.full_dispatch_request()
  File "C:\Users\delia\AppData\Local\Programs\Python\Python313\Lib\site-packages\flask\app.py", line 919, in full_dispatch_request
    rv = self.handle_user_exception(e)
  File "C:\Users\delia\AppData\Local\Programs\Python\Python313\Lib\site-packages\flask\app.py", line 917, in full_dispatch_request
    rv = self.dispatch_request()
  File "C:\Users\delia\AppData\Local\Programs\Python\Python313\Lib\site-packages\flask\app.py", line 902, in dispatch_request
    return self.ensure_sync(self.view_functions[rule.endpoint])(**view_args)  # type: ignore[no-any-return]
           ~~~~~~~~~~~~~~~~~~~~~~~~~~~~~~~~~~~~~~~~~~~~~~~~~~~~^^^^^^^^^^^^^
  File "C:\Local AI Chat\app.py", line 293, in api_draft_upload
    return ok_resp(item=att, total_tokens=_draft_total_tokens(items))
TypeError: ok_resp() got an unexpected keyword argument 'item'
ERROR:app:Exception on /api/chats/02b11af08e72/drafts/2efa844c-a480-4525-89ed-15990b40ba36/attachments [POST]
Traceback (most recent call last):
  File "C:\Users\delia\AppData\Local\Programs\Python\Python313\Lib\site-packages\flask\app.py", line 1511, in wsgi_app
    response = self.full_dispatch_request()
  File "C:\Users\delia\AppData\Local\Programs\Python\Python313\Lib\site-packages\flask\app.py", line 919, in full_dispatch_request
    rv = self.handle_user_exception(e)
  File "C:\Users\delia\AppData\Local\Programs\Python\Python313\Lib\site-packages\flask\app.py", line 917, in full_dispatch_request
    rv = self.dispatch_request()
  File "C:\Users\delia\AppData\Local\Programs\Python\Python313\Lib\site-packages\flask\app.py", line 902, in dispatch_request
    return self.ensure_sync(self.view_functions[rule.endpoint])(**view_args)  # type: ignore[no-any-return]
           ~~~~~~~~~~~~~~~~~~~~~~~~~~~~~~~~~~~~~~~~~~~~~~~~~~~~^^^^^^^^^^^^^
  File "C:\Local AI Chat\app.py", line 293, in api_draft_upload
    return ok_resp(item=att, total_tokens=_draft_total_tokens(items))
TypeError: ok_resp() got an unexpected keyword argument 'item'
ERROR:app:Exception on /api/chats/02b11af08e72/drafts/2efa844c-a480-4525-89ed-15990b40ba36/attachments [POST]
Traceback (most recent call last):
  File "C:\Users\delia\AppData\Local\Programs\Python\Python313\Lib\site-packages\flask\app.py", line 1511, in wsgi_app
    response = self.full_dispatch_request()
  File "C:\Users\delia\AppData\Local\Programs\Python\Python313\Lib\site-packages\flask\app.py", line 919, in full_dispatch_request
    rv = self.handle_user_exception(e)
  File "C:\Users\delia\AppData\Local\Programs\Python\Python313\Lib\site-packages\flask\app.py", line 917, in full_dispatch_request
    rv = self.dispatch_request()
  File "C:\Users\delia\AppData\Local\Programs\Python\Python313\Lib\site-packages\flask\app.py", line 902, in dispatch_request
    return self.ensure_sync(self.view_functions[rule.endpoint])(**view_args)  # type: ignore[no-any-return]
           ~~~~~~~~~~~~~~~~~~~~~~~~~~~~~~~~~~~~~~~~~~~~~~~~~~~~^^^^^^^^^^^^^
  File "C:\Local AI Chat\app.py", line 293, in api_draft_upload
    return ok_resp(item=att, total_tokens=_draft_total_tokens(items))
TypeError: ok_resp() got an unexpected keyword argument 'item'
ERROR:app:Exception on /api/chats/02b11af08e72/drafts/2efa844c-a480-4525-89ed-15990b40ba36/attachments [POST]
Traceback (most recent call last):
  File "C:\Users\delia\AppData\Local\Programs\Python\Python313\Lib\site-packages\flask\app.py", line 1511, in wsgi_app
    response = self.full_dispatch_request()
  File "C:\Users\delia\AppData\Local\Programs\Python\Python313\Lib\site-packages\flask\app.py", line 919, in full_dispatch_request
    rv = self.handle_user_exception(e)
  File "C:\Users\delia\AppData\Local\Programs\Python\Python313\Lib\site-packages\flask\app.py", line 917, in full_dispatch_request
    rv = self.dispatch_request()
  File "C:\Users\delia\AppData\Local\Programs\Python\Python313\Lib\site-packages\flask\app.py", line 902, in dispatch_request
    return self.ensure_sync(self.view_functions[rule.endpoint])(**view_args)  # type: ignore[no-any-return]
           ~~~~~~~~~~~~~~~~~~~~~~~~~~~~~~~~~~~~~~~~~~~~~~~~~~~~^^^^^^^^^^^^^
  File "C:\Local AI Chat\app.py", line 293, in api_draft_upload
    return ok_resp(item=att, total_tokens=_draft_total_tokens(items))
TypeError: ok_resp() got an unexpected keyword argument 'item'

Please fix and do not bloat the code, delete any unessacary code that becomes redundant after this update. Do not code sloppy.